[ 2025-04-23 03:57:37,469 ] 97 werkzeug - INFO - [31m[1mWARNING: This is a development server. Do not use it in a production deployment. Use a production WSGI server instead.[0m
 * Running on all addresses (0.0.0.0)
 * Running on http://127.0.0.1:5000
 * Running on http://192.168.74.208:5000
[ 2025-04-23 03:57:37,469 ] 97 werkzeug - INFO - [33mPress CTRL+C to quit[0m
[ 2025-04-23 04:00:04,492 ] 97 werkzeug - INFO - 127.0.0.1 - - [23/Apr/2025 04:00:04] "GET / HTTP/1.1" 200 -
[ 2025-04-23 04:00:04,525 ] 97 werkzeug - INFO - 127.0.0.1 - - [23/Apr/2025 04:00:04] "[33mGET /favicon.ico HTTP/1.1[0m" 404 -
[ 2025-04-23 04:01:02,962 ] 97 werkzeug - INFO - 127.0.0.1 - - [23/Apr/2025 04:01:02] "GET /predictdata HTTP/1.1" 200 -
[ 2025-04-23 04:02:25,102 ] 875 app - ERROR - Exception on /predictdata [POST]
Traceback (most recent call last):
  File "/home/shreya/Academic-performance-monitoring-system-using-ML/src/pipeline/predict_pipeline.py", line 13, in predict
    model_path=os.path.join("artifacts","model.pkl")
               ^^
NameError: name 'os' is not defined

During handling of the above exception, another exception occurred:

Traceback (most recent call last):
  File "/home/shreya/Academic-performance-monitoring-system-using-ML/venv/lib/python3.11/site-packages/flask/app.py", line 1511, in wsgi_app
    response = self.full_dispatch_request()
               ^^^^^^^^^^^^^^^^^^^^^^^^^^^^
  File "/home/shreya/Academic-performance-monitoring-system-using-ML/venv/lib/python3.11/site-packages/flask/app.py", line 919, in full_dispatch_request
    rv = self.handle_user_exception(e)
         ^^^^^^^^^^^^^^^^^^^^^^^^^^^^^
  File "/home/shreya/Academic-performance-monitoring-system-using-ML/venv/lib/python3.11/site-packages/flask/app.py", line 917, in full_dispatch_request
    rv = self.dispatch_request()
         ^^^^^^^^^^^^^^^^^^^^^^^
  File "/home/shreya/Academic-performance-monitoring-system-using-ML/venv/lib/python3.11/site-packages/flask/app.py", line 902, in dispatch_request
    return self.ensure_sync(self.view_functions[rule.endpoint])(**view_args)  # type: ignore[no-any-return]
           ^^^^^^^^^^^^^^^^^^^^^^^^^^^^^^^^^^^^^^^^^^^^^^^^^^^^^^^^^^^^^^^^^
  File "/home/shreya/Academic-performance-monitoring-system-using-ML/app.py", line 39, in predict_datapoint
    results=predict_pipeline.predict(pred_df)
            ^^^^^^^^^^^^^^^^^^^^^^^^^^^^^^^^^
  File "/home/shreya/Academic-performance-monitoring-system-using-ML/src/pipeline/predict_pipeline.py", line 24, in predict
    raise CustomException(e,sys)
src.exception.CustomException: Error occured in python script name [/home/shreya/Academic-performance-monitoring-system-using-ML/src/pipeline/predict_pipeline.py] line number [13] error message[name 'os' is not defined]
[ 2025-04-23 04:02:25,104 ] 97 werkzeug - INFO - 127.0.0.1 - - [23/Apr/2025 04:02:25] "[35m[1mPOST /predictdata HTTP/1.1[0m" 500 -
[ 2025-04-23 04:11:00,648 ] 875 app - ERROR - Exception on /predictdata [POST]
Traceback (most recent call last):
  File "/home/shreya/Academic-performance-monitoring-system-using-ML/src/pipeline/predict_pipeline.py", line 13, in predict
    model_path=os.path.join("artifacts","model.pkl")
               ^^
NameError: name 'os' is not defined

During handling of the above exception, another exception occurred:

Traceback (most recent call last):
  File "/home/shreya/Academic-performance-monitoring-system-using-ML/venv/lib/python3.11/site-packages/flask/app.py", line 1511, in wsgi_app
    response = self.full_dispatch_request()
               ^^^^^^^^^^^^^^^^^^^^^^^^^^^^
  File "/home/shreya/Academic-performance-monitoring-system-using-ML/venv/lib/python3.11/site-packages/flask/app.py", line 919, in full_dispatch_request
    rv = self.handle_user_exception(e)
         ^^^^^^^^^^^^^^^^^^^^^^^^^^^^^
  File "/home/shreya/Academic-performance-monitoring-system-using-ML/venv/lib/python3.11/site-packages/flask/app.py", line 917, in full_dispatch_request
    rv = self.dispatch_request()
         ^^^^^^^^^^^^^^^^^^^^^^^
  File "/home/shreya/Academic-performance-monitoring-system-using-ML/venv/lib/python3.11/site-packages/flask/app.py", line 902, in dispatch_request
    return self.ensure_sync(self.view_functions[rule.endpoint])(**view_args)  # type: ignore[no-any-return]
           ^^^^^^^^^^^^^^^^^^^^^^^^^^^^^^^^^^^^^^^^^^^^^^^^^^^^^^^^^^^^^^^^^
  File "/home/shreya/Academic-performance-monitoring-system-using-ML/app.py", line 39, in predict_datapoint
    results=predict_pipeline.predict(pred_df)
            ^^^^^^^^^^^^^^^^^^^^^^^^^^^^^^^^^
  File "/home/shreya/Academic-performance-monitoring-system-using-ML/src/pipeline/predict_pipeline.py", line 24, in predict
    raise CustomException(e,sys)
src.exception.CustomException: Error occured in python script name [/home/shreya/Academic-performance-monitoring-system-using-ML/src/pipeline/predict_pipeline.py] line number [13] error message[name 'os' is not defined]
[ 2025-04-23 04:11:00,649 ] 97 werkzeug - INFO - 127.0.0.1 - - [23/Apr/2025 04:11:00] "[35m[1mPOST /predictdata HTTP/1.1[0m" 500 -
